Workbook

Sheet Tổng quan
A1: Nico-tick — Tổng quan dự án
A2: Hôm nay | B2: =TODAY() | C2: Tab này tự tính từ tab Việc, đừng sửa. Cách dùng: xem tab Hướng dẫn.
A4: Các mốc
A5: Mốc | B5: Ngày | C5: Còn (ngày) | D5: Điều kiện đạt | E5: Nếu trượt thì
A6: Họp khởi động nhóm | B6: 46292 | C6: =IF(B6<TODAY(),"Đã qua",B6-TODAY()) | D6: Cả 3 đồng ý phân công, có giờ họp tuần | E6: Họp bù trong 2 ngày
A7: Họp thầy: chốt mô hình + phạm vi | B7: 46296 | C7: =IF(B7<TODAY(),"Đã qua",B7-TODAY()) | D7: Thầy trả lời 6 vấn đề mở (Q15–Q20) | E7: Gửi email hỏi các câu còn lại
A8: Khoá đề cương | B8: 46298 | C8: =IF(B8<TODAY(),"Đã qua",B8-TODAY()) | D8: README cập nhật theo quyết định của thầy | E8: —
A9: CHỐT 1 — GO/NO-GO dữ liệu | B9: 46308 | C9: =IF(B9<TODAY(),"Đã qua",B9-TODAY()) | D9: ≥150 DN × ≥8 năm × có ngày công bố | E9: Bỏ Bảng 2, H3 thành mục hạn chế, báo thầy trong ngày
A10: Xong hạ tầng đánh giá (P2) | B10: 46314 | C10: =IF(B10<TODAY(),"Đã qua",B10-TODAY()) | D10: Baseline thủ công chạy hết pipeline | E10: —
A11: CHỐT 2 — GO/NO-GO sinh công thức | B11: 46329 | C11: =IF(B11<TODAY(),"Đã qua",B11-TODAY()) | D11: Tỷ lệ công thức hợp lệ ≥60% | E11: Few-shot + ràng buộc grammar, không đổi mô hình
A12: Có Bảng 1 / 2 / 3 | B12: 46342 | C12: =IF(B12<TODAY(),"Đã qua",B12-TODAY()) | D12: 3 bảng kết quả có số | E12: —
A13: ĐÓNG BĂNG + nộp nháp GVHD | B13: 46356 | C13: =IF(B13<TODAY(),"Đã qua",B13-TODAY()) | D13: Không chạy thí nghiệm mới | E13: Không có phương án — không được trượt
A14: NỘP BÁO CÁO | B14: 46370 | C14: =IF(B14<TODAY(),"Đã qua",B14-TODAY()) | D14: Bản in xong từ 13/12 | E14: —
A16: Việc theo người
A17: Người | B17: Cần làm | C17: Đang làm | D17: Chờ duyệt | E17: Kẹt | F17: Xong | G17: Trễ | H17: Tổng
A18: Quân | B18: =COUNTIFS('Việc'!$D$2:$D$100,$A18,'Việc'!$I$2:$I$100,"Cần làm") | C18: =COUNTIFS('Việc'!$D$2:$D$100,$A18,'Việc'!$I$2:$I$100,"Đang làm") | D18: =COUNTIFS('Việc'!$D$2:$D$100,$A18,'Việc'!$I$2:$I$100,"Chờ duyệt") | E18: =COUNTIFS('Việc'!$D$2:$D$100,$A18,'Việc'!$I$2:$I$100,"Kẹt") | F18: =COUNTIFS('Việc'!$D$2:$D$100,$A18,'Việc'!$I$2:$I$100,"Xong") | G18: =COUNTIFS('Việc'!$D$2:$D$100,$A18,'Việc'!$J$2:$J$100,"TRỄ") | H18: =SUM(B18:F18)
A19: Thắng | B19: =COUNTIFS('Việc'!$D$2:$D$100,$A19,'Việc'!$I$2:$I$100,"Cần làm") | C19: =COUNTIFS('Việc'!$D$2:$D$100,$A19,'Việc'!$I$2:$I$100,"Đang làm") | D19: =COUNTIFS('Việc'!$D$2:$D$100,$A19,'Việc'!$I$2:$I$100,"Chờ duyệt") | E19: =COUNTIFS('Việc'!$D$2:$D$100,$A19,'Việc'!$I$2:$I$100,"Kẹt") | F19: =COUNTIFS('Việc'!$D$2:$D$100,$A19,'Việc'!$I$2:$I$100,"Xong") | G19: =COUNTIFS('Việc'!$D$2:$D$100,$A19,'Việc'!$J$2:$J$100,"TRỄ") | H19: =SUM(B19:F19)
A20: Trung | B20: =COUNTIFS('Việc'!$D$2:$D$100,$A20,'Việc'!$I$2:$I$100,"Cần làm") | C20: =COUNTIFS('Việc'!$D$2:$D$100,$A20,'Việc'!$I$2:$I$100,"Đang làm") | D20: =COUNTIFS('Việc'!$D$2:$D$100,$A20,'Việc'!$I$2:$I$100,"Chờ duyệt") | E20: =COUNTIFS('Việc'!$D$2:$D$100,$A20,'Việc'!$I$2:$I$100,"Kẹt") | F20: =COUNTIFS('Việc'!$D$2:$D$100,$A20,'Việc'!$I$2:$I$100,"Xong") | G20: =COUNTIFS('Việc'!$D$2:$D$100,$A20,'Việc'!$J$2:$J$100,"TRỄ") | H20: =SUM(B20:F20)
A21: Việc giao cho "Cả nhóm" không có — mỗi việc đúng 1 người phụ trách (cột Phụ trách).

Sheet Việc
A1: ID | B1: Pha | C1: Việc | D1: Phụ trách | E1: Hỗ trợ | F1: Bắt đầu | G1: Hạn | H1: Hạn mới | I1: Trạng thái | J1: Trễ? | K1: Xong khi (đầu ra) | L1: Phụ thuộc | M1: TL# | N1: Ghi chú
A2: V01 | B2: PM | C2: Dựng bộ quản lý dự án (Google Sheet + docs/pm) | D2: Quân | F2: 46291 | G2: 46291 | I2: Xong | J2: =IF(OR(I2="Xong",I2="Huỷ",G2=""),"",IF(IF(H2="",G2,H2)<TODAY(),"TRỄ",IF(IF(H2="",G2,H2)-TODAY()<=2,"Sắp hạn",""))) | K2: Sheet + docs/pm/ có đủ phân công, việc, rủi ro, quyết định, họp
A3: V02 | B3: PM | C3: Họp khởi động: trình bày phân công, xin ý kiến Thắng & Trung, chốt giờ họp tuần cố định | D3: Quân | E3: Thắng, Trung | F3: 46292 | G3: 46292 | I3: Cần làm | J3: =IF(OR(I3="Xong",I3="Huỷ",G3=""),"",IF(IF(H3="",G3,H3)<TODAY(),"TRỄ",IF(IF(H3="",G3,H3)-TODAY()<=2,"Sắp hạn",""))) | K3: Cả 3 đồng ý phân công (hoặc đã sửa), có giờ họp tuần, Sheet đã share cho 2 bạn | L3: V01 | N3: Phân công hiện là ĐỀ XUẤT, chốt ở buổi này
A4: V03 | B4: P0 | C4: Bộ thử 76 prompt, 4 họ F1–F4 | D4: Quân | F4: 46284 | G4: 46289 | I4: Xong | J4: =IF(OR(I4="Xong",I4="Huỷ",G4=""),"",IF(IF(H4="",G4,H4)<TODAY(),"TRỄ",IF(IF(H4="",G4,H4)-TODAY()<=2,"Sắp hạn",""))) | K4: eval/prompts.jsonl đủ 76 dòng | M4: 1
A5: V04 | B5: P0 | C5: Benchmark 4 mô hình × 76 prompt × 3 seed | D5: Quân | F5: 46284 | G5: 46289 | I5: Xong | J5: =IF(OR(I5="Xong",I5="Huỷ",G5=""),"",IF(IF(H5="",G5,H5)<TODAY(),"TRỄ",IF(IF(H5="",G5,H5)-TODAY()<=2,"Sắp hạn",""))) | K5: bench/results/table.md | L5: V03 | M5: 2 | N5: Kaggle T4, NF4 4-bit
A6: V05 | B6: P0 | C6: Viết thang chấm eval/rubric.md cho tiêu chí C4 (ý nghĩa kinh tế, 1–5) | D6: Quân | E6: Thắng, Trung | F6: 46287 | G6: 46289 | H6: 46292 | I6: Chờ duyệt | J6: =IF(OR(I6="Xong",I6="Huỷ",G6=""),"",IF(IF(H6="",G6,H6)<TODAY(),"TRỄ",IF(IF(H6="",G6,H6)-TODAY()<=2,"Sắp hạn",""))) | K6: Mỗi mức 1–5 có mô tả + ví dụ; Thắng, Trung đọc và hỏi hết chỗ chưa rõ | N6: Bản nháp đã có 26/09. Việc con 1.5 của P0, trễ từ 24/09
A7: V06 | B7: P0 | C7: Hiệu chỉnh C4: Thắng, Trung chấm độc lập C001–C010, chạy c4_merge.py --only C001-C010 | D7: Trung | E7: Thắng | F7: 46293 | G7: 46293 | I7: Cần làm | J7: =IF(OR(I7="Xong",I7="Huỷ",G7=""),"",IF(IF(H7="",G7,H7)<TODAY(),"TRỄ",IF(IF(H7="",G7,H7)-TODAY()<=2,"Sắp hạn",""))) | K7: Không quá 3/10 công thức lệch ≥2 điểm; quá thì sửa rubric rồi chấm lại | L7: V05 | N7: Quy trình: eval/rubric.md mục 7
A8: V07 | B8: P0 | C8: Chấm C4 C011–C080 (2 người độc lập, mù tên mô hình) + trọng tài công thức lệch ≥2 | D8: Trung | E8: Thắng, Quân | F8: 46293 | G8: 46289 | H8: 46294 | I8: Cần làm | J8: =IF(OR(I8="Xong",I8="Huỷ",G8=""),"",IF(IF(H8="",G8,H8)<TODAY(),"TRỄ",IF(IF(H8="",G8,H8)-TODAY()<=2,"Sắp hạn",""))) | K8: c4_scores_thang.csv + c4_scores_trung.csv đủ 80; c4_merge.py ra bench/results/c4.md | L8: V06 | M8: 2 | N8: Quân làm trọng tài, không chấm (đã xem output nhiều, dễ đoán ra mô hình). Việc con 2.6, trễ từ 24/09
A9: V08 | B9: P0 | C9: Tờ trình 1 trang chốt mô hình | D9: Quân | F9: 46287 | G9: 46289 | H9: 46294 | I9: Cần làm | J9: =IF(OR(I9="Xong",I9="Huỷ",G9=""),"",IF(IF(H9="",G9,H9)<TODAY(),"TRỄ",IF(IF(H9="",G9,H9)-TODAY()<=2,"Sắp hạn",""))) | K9: docs/to_trinh_chot_mo_hinh.docx đúng 5 khối, có bảng benchmark + điểm C4 | L9: V07 | M9: 3 | N9: Trễ từ 24/09
A10: V09 | B10: P0 | C10: Duyệt tờ trình (đọc như thầy đọc) | D10: Thắng | F10: 46295 | G10: 46295 | I10: Cần làm | J10: =IF(OR(I10="Xong",I10="Huỷ",G10=""),"",IF(IF(H10="",G10,H10)<TODAY(),"TRỄ",IF(IF(H10="",G10,H10)-TODAY()<=2,"Sắp hạn",""))) | K10: Góp ý gửi Quân, Quân sửa xong trong ngày | L10: V08 | M10: 3
A11: V10 | B11: P0 | C11: Gửi thầy tờ trình + 6 câu hỏi cần quyết (README mục 10) | D11: Quân | F11: 46295 | G11: 46295 | I11: Cần làm | J11: =IF(OR(I11="Xong",I11="Huỷ",G11=""),"",IF(IF(H11="",G11,H11)<TODAY(),"TRỄ",IF(IF(H11="",G11,H11)-TODAY()<=2,"Sắp hạn",""))) | K11: Email đã gửi, thầy có ≥1 ngày để đọc trước buổi họp | L11: V09
A12: V11 | B12: P0 | C12: Họp thầy: chốt mô hình + phạm vi | D12: Quân | E12: Thắng, Trung | F12: 46296 | G12: 46296 | I12: Cần làm | J12: =IF(OR(I12="Xong",I12="Huỷ",G12=""),"",IF(IF(H12="",G12,H12)<TODAY(),"TRỄ",IF(IF(H12="",G12,H12)-TODAY()<=2,"Sắp hạn",""))) | K12: Có câu trả lời cho 6 vấn đề mở | L12: V10 | M12: 4 | N12: Chương trình họp: docs/pm/bien_ban/2026-10-01_hop_thay.md
A13: V12 | B13: P0 | C13: Gửi biên bản họp thầy + cập nhật tab Quyết định | D13: Trung | E13: Quân | F13: 46296 | G13: 46297 | I13: Cần làm | J13: =IF(OR(I13="Xong",I13="Huỷ",G13=""),"",IF(IF(H13="",G13,H13)<TODAY(),"TRỄ",IF(IF(H13="",G13,H13)-TODAY()<=2,"Sắp hạn",""))) | K13: Biên bản trong docs/pm/bien_ban/, các Q15–Q20 chuyển sang Đã chốt | L13: V11 | N13: Người ghi biên bản luân phiên, lần này Trung
A14: V13 | B14: P0 | C14: Khoá đề cương | D14: Quân | E14: Thắng, Trung | F14: 46297 | G14: 46298 | I14: Cần làm | J14: =IF(OR(I14="Xong",I14="Huỷ",G14=""),"",IF(IF(H14="",G14,H14)<TODAY(),"TRỄ",IF(IF(H14="",G14,H14)-TODAY()<=2,"Sắp hạn",""))) | K14: README cập nhật theo quyết định của thầy; từ đây không đổi phạm vi | L14: V12 | M14: 5
A15: V14 | B15: P1 | C15: Dò nguồn ngày công bố BCTC thực tế (HOSE/HNX, vnstock, CafeF…), thử trên 20 mã mẫu | D15: Thắng | F15: 46292 | G15: 46295 | I15: Cần làm | J15: =IF(OR(I15="Xong",I15="Huỷ",G15=""),"",IF(IF(H15="",G15,H15)<TODAY(),"TRỄ",IF(IF(H15="",G15,H15)-TODAY()<=2,"Sắp hạn",""))) | K15: Ghi chú 1 trang: nguồn nào, phủ bao nhiêu mã × năm, cách lấy, độ tin cậy | M15: 7 | N15: Mang kết quả đi họp 01/10. Xem rủi ro R01
A16: V15 | B16: P1 | C16: Thu thập ngày công bố thực tế ~200 DN × 10 năm, đối chiếu chéo vnstock | D16: Thắng | F16: 46289 | G16: 46304 | I16: Cần làm | J16: =IF(OR(I16="Xong",I16="Huỷ",G16=""),"",IF(IF(H16="",G16,H16)<TODAY(),"TRỄ",IF(IF(H16="",G16,H16)-TODAY()<=2,"Sắp hạn",""))) | K16: File ngày công bố cho ≥150 DN × ≥8 năm | L16: V14 | M16: 7 | N16: Kế hoạch gốc bắt đầu 24/09 nhưng chưa giao → đang trễ bắt đầu
A17: V16 | B17: P1 | C17: Crawl BCTC quý ~200 DN × 10 năm (bảng số), map về config/variables.yaml | D17: Thắng | E17: Quân | F17: 46289 | G17: 46307 | I17: Cần làm | J17: =IF(OR(I17="Xong",I17="Huỷ",G17=""),"",IF(IF(H17="",G17,H17)<TODAY(),"TRỄ",IF(IF(H17="",G17,H17)-TODAY()<=2,"Sắp hạn",""))) | K17: Bảng số quý ≥150 DN × ≥8 năm, map đủ biến trong variables.yaml | L17: V11 | M17: 6 | N17: Phần bảng số qua vnstock làm ngay, không chờ họp. Nguồn thuyết minh chờ thầy chốt (Q15)
A18: V17 | B18: P1 | C18: Giá OHLCV theo ngày + mã ngành, gồm cả mã đã huỷ niêm yết | D18: Thắng | E18: Trung | F18: 46294 | G18: 46307 | I18: Cần làm | J18: =IF(OR(I18="Xong",I18="Huỷ",G18=""),"",IF(IF(H18="",G18,H18)<TODAY(),"TRỄ",IF(IF(H18="",G18,H18)-TODAY()<=2,"Sắp hạn",""))) | K18: Giá ngày đủ 10 năm, có mã huỷ niêm yết, căn đúng lịch giao dịch | M18: 8 | N18: Trung quy định định dạng cần cho backtest
A19: V18 | B19: P1 | C19: CHỐT 1 — GO/NO-GO: ≥150 DN × ≥8 năm × có ngày công bố? | D19: Quân | E19: Thắng, Trung | F19: 46308 | G19: 46308 | I19: Cần làm | J19: =IF(OR(I19="Xong",I19="Huỷ",G19=""),"",IF(IF(H19="",G19,H19)<TODAY(),"TRỄ",IF(IF(H19="",G19,H19)-TODAY()<=2,"Sắp hạn",""))) | K19: Quyết định GO/NO-GO ghi vào tab Quyết định, báo thầy trong ngày | L19: V15, V16, V17 | M19: 9 | N19: NO-GO → bỏ Bảng 2, H3 thành mục hạn chế
A20: V19 | B20: P2 | C20: Pipeline backtest: xếp hạng lát cắt ngang, long-short, IC, Sharpe, turnover | D20: Trung | F20: 46294 | G20: 46312 | I20: Cần làm | J20: =IF(OR(I20="Xong",I20="Huỷ",G20=""),"",IF(IF(H20="",G20,H20)<TODAY(),"TRỄ",IF(IF(H20="",G20,H20)-TODAY()<=2,"Sắp hạn",""))) | K20: Chạy được trên dữ liệu mẫu/giả, ra IC + Sharpe + turnover | M20: 10 | N20: Kế hoạch gốc bắt đầu 06/10; kéo sớm vì Trung đang ít việc P0
A21: V20 | B21: P2 | C21: Mô hình chi phí VN: phí môi giới 2 chiều, thuế bán 0,1%, spread theo thanh khoản, market impact | D21: Trung | F21: 46308 | G21: 46314 | I21: Cần làm | J21: =IF(OR(I21="Xong",I21="Huỷ",G21=""),"",IF(IF(H21="",G21,H21)<TODAY(),"TRỄ",IF(IF(H21="",G21,H21)-TODAY()<=2,"Sắp hạn",""))) | K21: Hàm chi phí gắn vào backtest, có bảng tham số và nguồn trích dẫn | L21: V19 | M21: 11 | N21: KHÔNG CẮT
A22: V21 | B22: P2 | C22: Baseline nhân tố thủ công (P/E, P/B, ROE, momentum, accruals) chạy hết pipeline | D22: Trung | F22: 46308 | G22: 46314 | I22: Cần làm | J22: =IF(OR(I22="Xong",I22="Huỷ",G22=""),"",IF(IF(H22="",G22,H22)<TODAY(),"TRỄ",IF(IF(H22="",G22,H22)-TODAY()<=2,"Sắp hạn",""))) | K22: Dòng đầu Bảng 1 có số | L22: V16, V17, V19 | M22: 12
A23: V22 | B23: P2 | C23: Bộ tính công thức DSL → số (dùng chung parser với validator) | D23: Trung | E23: Quân | F23: 46301 | G23: 46314 | I23: Cần làm | J23: =IF(OR(I23="Xong",I23="Huỷ",G23=""),"",IF(IF(H23="",G23,H23)<TODAY(),"TRỄ",IF(IF(H23="",G23,H23)-TODAY()<=2,"Sắp hạn",""))) | K23: Mọi công thức hợp lệ trong benchmark P0 tính ra được số | N23: README mục 10: cầu nối khối 2 → khối 3
A24: V23 | B24: P3 | C24: Chunk thuyết minh + index PhoBERT-base + bộ truy xuất | D24: Thắng | E24: Quân | F24: 46308 | G24: 46321 | I24: Cần làm | J24: =IF(OR(I24="Xong",I24="Huỷ",G24=""),"",IF(IF(H24="",G24,H24)<TODAY(),"TRỄ",IF(IF(H24="",G24,H24)-TODAY()<=2,"Sắp hạn",""))) | K24: Truy vấn → trả về top-k đoạn thuyết minh | L24: V16 | M24: 13
A25: V24 | B25: P3 | C25: Đánh giá truy xuất trên 50 truy vấn gán nhãn tay | D25: Thắng | E25: Quân | F25: 46317 | G25: 46321 | I25: Cần làm | J25: =IF(OR(I25="Xong",I25="Huỷ",G25=""),"",IF(IF(H25="",G25,H25)<TODAY(),"TRỄ",IF(IF(H25="",G25,H25)-TODAY()<=2,"Sắp hạn",""))) | K25: Bảng recall@k / MRR trên 50 truy vấn | L25: V23 | M25: 14 | N25: Số này để trả lời câu: sao cần 2 mô hình
A26: V25 | B26: P4 | C26: Thử giải mã ràng buộc ngữ pháp (GCD) trên bộ benchmark | D26: Quân | F26: 46301 | G26: 46312 | I26: Cần làm | J26: =IF(OR(I26="Xong",I26="Huỷ",G26=""),"",IF(IF(H26="",G26,H26)<TODAY(),"TRỄ",IF(IF(H26="",G26,H26)-TODAY()<=2,"Sắp hạn",""))) | K26: So sánh tỷ lệ hợp lệ có GCD vs không, cùng mô hình | L26: V13 | N26: Phòng rủi ro R03
A27: V26 | B27: P4 | C27: Validator đầy đủ: loại trích dẫn bịa + khử trùng theo tương quan | D27: Quân | F27: 46315 | G27: 46321 | I27: Cần làm | J27: =IF(OR(I27="Xong",I27="Huỷ",G27=""),"",IF(IF(H27="",G27,H27)<TODAY(),"TRỄ",IF(IF(H27="",G27,H27)-TODAY()<=2,"Sắp hạn",""))) | K27: Validator có đủ 2 bước mới, có test | L27: V22 | M27: 15
A28: V27 | B28: P4 | C28: Sinh ~150 công thức + truy vết nguồn, log tổng số đã thử | D28: Quân | F28: 46322 | G28: 46328 | I28: Cần làm | J28: =IF(OR(I28="Xong",I28="Huỷ",G28=""),"",IF(IF(H28="",G28,H28)<TODAY(),"TRỄ",IF(IF(H28="",G28,H28)-TODAY()<=2,"Sắp hạn",""))) | K28: ~150 công thức hợp lệ, mỗi công thức có nguồn; log tổng số lần thử | L28: V25, V26 | M28: 16
A29: V28 | B29: P4 | C29: HITL: duyệt công thức + biên bản lý do loại từng công thức | D29: Thắng | E29: Trung | F29: 46322 | G29: 46328 | I29: Cần làm | J29: =IF(OR(I29="Xong",I29="Huỷ",G29=""),"",IF(IF(H29="",G29,H29)<TODAY(),"TRỄ",IF(IF(H29="",G29,H29)-TODAY()<=2,"Sắp hạn",""))) | K29: Mỗi công thức có điểm + lý do giữ/loại | L29: V27 | M29: 17 | N29: Người sinh công thức (Quân) không tự duyệt
A30: V29 | B30: P4 | C30: CHỐT 2 — GO/NO-GO: tỷ lệ công thức hợp lệ ≥60%? | D30: Quân | E30: Thắng, Trung | F30: 46329 | G30: 46329 | I30: Cần làm | J30: =IF(OR(I30="Xong",I30="Huỷ",G30=""),"",IF(IF(H30="",G30,H30)<TODAY(),"TRỄ",IF(IF(H30="",G30,H30)-TODAY()<=2,"Sắp hạn",""))) | K30: Quyết định ghi vào tab Quyết định | L30: V27 | M30: 18 | N30: NO-GO → few-shot + grammar, không đổi mô hình
A31: V30 | B31: P5 | C31: Gán point-in-time theo ngày công bố + bản ngây thơ theo ngày cuối quý | D31: Trung | F31: 46329 | G31: 46335 | I31: Cần làm | J31: =IF(OR(I31="Xong",I31="Huỷ",G31=""),"",IF(IF(H31="",G31,H31)<TODAY(),"TRỄ",IF(IF(H31="",G31,H31)-TODAY()<=2,"Sắp hạn",""))) | K31: 2 bộ giá trị nhân tố song song → Bảng 2 | L31: V15, V22 | M31: 19
A32: V31 | B32: P5 | C32: LightGBM + MLP (+ tuyến tính nếu thầy duyệt H5), walk-forward | D32: Trung | F32: 46329 | G32: 46342 | I32: Cần làm | J32: =IF(OR(I32="Xong",I32="Huỷ",G32=""),"",IF(IF(H32="",G32,H32)<TODAY(),"TRỄ",IF(IF(H32="",G32,H32)-TODAY()<=2,"Sắp hạn",""))) | K32: Mô hình huấn luyện walk-forward, chọn tham số chỉ trên quá khứ | L32: V30 | M32: 20 | N32: Không dùng LLM chọn feature theo kết quả
A33: V32 | B33: P5 | C33: Backtest đầy đủ, xuất Bảng 1 / 2 / 3 | D33: Trung | E33: Quân | F33: 46336 | G33: 46342 | I33: Cần làm | J33: =IF(OR(I33="Xong",I33="Huỷ",G33=""),"",IF(IF(H33="",G33,H33)<TODAY(),"TRỄ",IF(IF(H33="",G33,H33)-TODAY()<=2,"Sắp hạn",""))) | K33: 3 bảng kết quả có số | L33: V20, V31 | M33: 21 | N33: Xương sống của bài
A34: V33 | B34: P6 | C34: Baseline API trên mẫu con 50 DN × 3 năm | D34: Quân | F34: 46343 | G34: 46349 | I34: Cần làm | J34: =IF(OR(I34="Xong",I34="Huỷ",G34=""),"",IF(IF(H34="",G34,H34)<TODAY(),"TRỄ",IF(IF(H34="",G34,H34)-TODAY()<=2,"Sắp hạn",""))) | K34: Dòng baseline API trong Bảng 1 | L34: V32 | M34: 22
A35: V34 | B35: P6 | C35: Ablation 2 cấu hình: bỏ RAG, bỏ HITL | D35: Thắng | E35: Quân | F35: 46343 | G35: 46349 | I35: Cần làm | J35: =IF(OR(I35="Xong",I35="Huỷ",G35=""),"",IF(IF(H35="",G35,H35)<TODAY(),"TRỄ",IF(IF(H35="",G35,H35)-TODAY()<=2,"Sắp hạn",""))) | K35: Dòng ablation trong Bảng 1 | L35: V32 | M35: 23
A36: V35 | B36: P6 | C36: Demo Streamlit 1 màn hình: nhập mã → công thức + đoạn nguồn + xếp hạng | D36: Thắng | F36: 46343 | G36: 46356 | I36: Cần làm | J36: =IF(OR(I36="Xong",I36="Huỷ",G36=""),"",IF(IF(H36="",G36,H36)<TODAY(),"TRỄ",IF(IF(H36="",G36,H36)-TODAY()<=2,"Sắp hạn",""))) | K36: Thầy bấm thử được trên máy khác | L36: V32 | M36: 24
A37: V36 | B37: P7 | C37: Kiểm định: t-stat, sai số chuẩn, giai đoạn con, hiệu chỉnh đa giả thuyết | D37: Trung | F37: 46350 | G37: 46356 | I37: Cần làm | J37: =IF(OR(I37="Xong",I37="Huỷ",G37=""),"",IF(IF(H37="",G37,H37)<TODAY(),"TRỄ",IF(IF(H37="",G37,H37)-TODAY()<=2,"Sắp hạn",""))) | K37: Mọi số trong Bảng 1/2/3 có t-stat + sai số chuẩn | L37: V32 | M37: 25 | N37: KHÔNG CẮT
A38: V37 | B38: P7 | C38: ĐÓNG BĂNG KẾT QUẢ | D38: Quân | E38: Thắng, Trung | F38: 46356 | G38: 46356 | I38: Cần làm | J38: =IF(OR(I38="Xong",I38="Huỷ",G38=""),"",IF(IF(H38="",G38,H38)<TODAY(),"TRỄ",IF(IF(H38="",G38,H38)-TODAY()<=2,"Sắp hạn",""))) | K38: Không chạy thí nghiệm mới sau mốc này | L38: V36 | M38: 26
A39: V38 | B39: P8 | C39: Chương 1–2: tổng quan, khoảng trống, cơ sở lý thuyết | D39: Thắng | E39: Quân | F39: 46315 | G39: 46335 | I39: Cần làm | J39: =IF(OR(I39="Xong",I39="Huỷ",G39=""),"",IF(IF(H39="",G39,H39)<TODAY(),"TRỄ",IF(IF(H39="",G39,H39)-TODAY()<=2,"Sắp hạn",""))) | K39: Bản nháp đủ 2 chương | M39: 27 | N39: Nguồn chính: docs/GAP_research.pdf
A40: V39 | B40: P8 | C40: Chương 3: phương pháp — mỗi người viết phần mình làm, Quân gom | D40: Quân | E40: Thắng, Trung | F40: 46329 | G40: 46342 | I40: Cần làm | J40: =IF(OR(I40="Xong",I40="Huỷ",G40=""),"",IF(IF(H40="",G40,H40)<TODAY(),"TRỄ",IF(IF(H40="",G40,H40)-TODAY()<=2,"Sắp hạn",""))) | K40: Bản nháp Chương 3 | M40: 28 | N40: Căn cứ chọn mô hình lấy từ tờ trình
...

Sheet Phân công
A1: Người | B1: Vai chính | C1: Vai phụ | D1: Phụ trách chính (pha) | E1: Hỗ trợ (pha) | F1: Trách nhiệm cụ thể | G1: Liên hệ (SĐT / email)
A2: Quân | B2: Quản lý dự án (PM) · ML: bộ sinh công thức | C2: Liên lạc GVHD · gom báo cáo | D2: P0, P4, P6 (baseline API) · chủ trì 3 mốc GO/NO-GO | E2: P3, P5, P8 | F2: Kế hoạch & tiến độ, họp tuần, liên lạc thầy; benchmark, validator, GCD, sinh công thức, baseline API; gom Chương 3 và bản nộp
A3: Thắng | B3: Data | C3: ML: RAG · Dev: demo · chủ trì Chương 1–2 | D3: P1, P3, P6 (ablation, demo) | E3: P0 (duyệt tờ trình), P4 (chủ trì HITL), P8 | F3: Crawl BCTC quý, ngày công bố, giá ngày; chunk thuyết minh + PhoBERT + đánh giá truy xuất; demo Streamlit; duyệt công thức; format báo cáo
A4: Trung | B4: Quant | C4: Chủ trì Chương 4–5 | D4: P2, P5, P7 | E4: P0 (chấm C4), P1 (định dạng giá), P4 (HITL), P8 | F4: Backtest, mô hình chi phí VN, baseline thủ công, bộ tính công thức → số; point-in-time, LightGBM/MLP, Bảng 1/2/3; kiểm định thống kê
A6: Ô vàng: mỗi người tự điền liên hệ. Phân công này là ĐỀ XUẤT — chốt ở họp khởi động 27/09 (Q12).

Sheet Ma trận
A1: Pha | B1: Nội dung | C1: Hạn | D1: Quân | E1: Thắng | F1: Trung | G1: Ghi chú
A2: P0 | B2: Chốt mô hình | C2: 03/10 | D2: Chính | E2: Hỗ trợ | F2: Hỗ trợ | G2: Thắng duyệt tờ trình; Trung chấm C4, ghi biên bản họp thầy
A3: P1 | B3: Dữ liệu | C3: 12/10 · CHỐT 1: 13/10 | D3: Duyệt | E3: Chính | F3: Hỗ trợ | G3: Trung quy định định dạng giá cho backtest
A4: P2 | B4: Hạ tầng đánh giá | C4: 19/10 | D4: Hỗ trợ | E4: Hỗ trợ | F4: Chính | G4: Quân: parser DSL dùng chung; Thắng: dữ liệu giá
A5: P3 | B5: Encoder + RAG | C5: 26/10 | D5: Duyệt | E5: Chính | F5: —
A6: P4 | B6: Sinh công thức | C6: 02/11 · CHỐT 2: 03/11 | D6: Chính | E6: Hỗ trợ | F6: Hỗ trợ | G6: Thắng chủ trì duyệt HITL — người sinh công thức không tự duyệt
A7: P5 | B7: Mô hình nhân tố | C7: 16/11 | D7: Duyệt | E7: — | F7: Chính
A8: P6 | B8: Đối chứng + demo | C8: 23/11 | D8: Chính | E8: Chính | F8: — | G8: Quân: baseline API · Thắng: ablation, demo
A9: P7 | B9: Kiểm định | C9: 30/11 | D9: Duyệt | E9: — | F9: Chính
A10: P8 | B10: Báo cáo | C10: 14/12 | D10: Chính | E10: Hỗ trợ | F10: Hỗ trợ | G10: Quân: Ch.3 + gom · Thắng: Ch.1–2, format · Trung: Ch.4–5
A11: P9 | B11: Bảo vệ | C11: sau 14/12 | D11: Chính | E11: Hỗ trợ | F11: Hỗ trợ
A13: Chính = chịu trách nhiệm kết quả của pha · Hỗ trợ = làm một phần theo yêu cầu người Chính · Duyệt = xem và đồng ý đầu ra trước khi đóng pha

Sheet Rủi ro
A1: ID | B1: Rủi ro | C1: Nhóm | D1: Khả năng (1–3) | E1: Ảnh hưởng (1–3) | F1: Điểm | G1: Dấu hiệu sớm | H1: Cách phòng | I1: Nếu xảy ra thì | J1: Người theo dõi | K1: Trạng thái | L1: Cập nhật
A2: R01 | B2: Không tìm được nguồn ngày công bố BCTC thực tế đủ phủ | C2: Dữ liệu | D2: 3 | E2: 3 | F2: =IF(OR(D2="",E2=""),"",D2*E2) | G2: Đến 30/09 (V14) chưa nguồn nào phủ >50% mã × năm | H2: Dò nguồn ngay tuần này, thử nhiều nguồn song song, hỏi thầy 01/10 | I2: Bỏ Bảng 2, chuyển H3 thành mục hạn chế, báo thầy trong ngày (CHỐT 1) | J2: Thắng | K2: Mở | L2: 46291
A3: R02 | B3: Không có thuyết minh BCTC quý (API chỉ trả bảng số) | C3: Dữ liệu | D3: 3 | E3: 2 | F3: =IF(OR(D3="",E3=""),"",D3*E3) | G3: Thầy không có hướng khác ở buổi 01/10 | H3: Đề xuất với thầy dùng thuyết minh năm | I3: Dùng thuyết minh năm, áp cho 4 quý sau ngày công bố | J3: Thắng | K3: Mở | L3: 46291
A4: R03 | B4: Tỷ lệ công thức hợp lệ < 60% ở CHỐT 2 (hiện tốt nhất 47,2%) | C4: Mô hình | D4: 2 | E4: 3 | F4: =IF(OR(D4="",E4=""),"",D4*E4) | G4: GCD (V25) không đưa được tỷ lệ lên ≥55% trước 17/10 | H4: Thử GCD sớm, trước P4 | I4: Few-shot + ràng buộc grammar, KHÔNG đổi mô hình lần nữa | J4: Quân | K4: Mở | L4: 46291
A5: R04 | B5: Thiếu biến để tính nhân tố (parser OCR chỉ đọc trung vị 30/65 biến) | C5: Dữ liệu | D5: 2 | E5: 3 | F5: =IF(OR(D5="",E5=""),"",D5*E5) | G5: Sau khi map API, <80% biến trong variables.yaml có số | H5: Lấy số liệu quý từ API, map variables.yaml sang tên trường API | I5: Thu hẹp danh mục biến, ghi rõ trong phần hạn chế | J5: Thắng | K5: Mở | L5: 46291
A6: R05 | B6: Ít điểm thời gian (~40 quý) → kết quả không có ý nghĩa thống kê | C6: Phương pháp | D6: 2 | E6: 3 | F6: =IF(OR(D6="",E6=""),"",D6*E6) | G6: t-stat của IC < 2 ở hầu hết cấu hình | H6: Bổ sung giá tần suất ngày (Wei et al. 2022), kiểm định kỹ ở P7 | I6: Báo cáo trung thực, nhấn mạnh đóng góp của Bảng 2 và Bảng 3 | J6: Trung | K6: Mở | L6: 46291
A7: R06 | B7: Rò rỉ dữ liệu tương lai (point-in-time, mốc huấn luyện LLM) bị hội đồng bắt lỗi | C7: Phương pháp | D7: 2 | E7: 3 | F7: =IF(OR(D7="",E7=""),"",D7*E7) | G7: Code gán thời gian chưa ai review chéo | H7: Theo kỷ luật README mục 6; người khác review code gán thời gian | I7: Sửa và chạy lại trước 30/11; sau đóng băng thì ghi vào hạn chế | J7: Trung | K7: Mở | L7: 46291
A8: R07 | B8: Quá tải 1 người: Quân vừa quản lý vừa làm ML chính (hiện mọi commit là của Quân) | C8: Nhân sự | D8: 3 | E8: 2 | F8: =IF(OR(D8="",E8=""),"",D8*E8) | G8: Việc của Quân trễ 2 tuần liên tiếp; Thắng/Trung chưa có commit | H8: Giao việc theo tên, soi bảng Tổng quan mỗi buổi họp tuần | I8: Chuyển bớt việc P6/P8 của Quân sang người đang ít việc | J8: Quân | K8: Mở | L8: 46291
A9: R08 | B9: Dồn việc viết báo cáo về cuối, không đủ 10 ngày cho thầy sửa | C9: Tiến độ | D9: 2 | E9: 3 | F9: =IF(OR(D9="",E9=""),"",D9*E9) | G9: Đến 09/11 chưa có nháp Chương 1–2 | H9: Viết Chương 1–2 từ 20/10, song song với chạy mô hình | I9: Cắt độ dài Chương 2, ưu tiên Chương 3–4 | J9: Quân | K9: Mở | L9: 46291
A10: R09 | B10: Thầy không chấp nhận bộ sinh 5,1B tổng (Gemma) vì muốn "vài trăm triệu" | C10: Phạm vi | D10: 2 | E10: 2 | F10: =IF(OR(D10="",E10=""),"",D10*E10) | G10: Buổi 01/10 thầy nghiêng về mô hình <1B | H10: Tờ trình dẫn số VRAM và kết quả Qwen3.5-0.8B chỉ 16% hợp lệ | I10: Chuyển sang Qwen3.5-2B (dự phòng đã có số) | J10: Quân | K10: Mở | L10: 46291
A11: R10 | B11: Phạm vi phình ra sau khi khoá đề cương (thêm giả thuyết, thêm mô hình…) | C11: Phạm vi | D11: 2 | E11: 2 | F11: =IF(OR(D11="",E11=""),"",D11*E11) | G11: Có việc mới không nằm trong tab Việc | H11: Sau 03/10, ý mới ghi vào mục "để sau", chỉ đổi khi thầy yêu cầu | I11: Đổi phạm vi = ghi vào tab Quyết định, bỏ bớt 1 việc tương đương | J11: Quân | K11: Mở | L11: 46291
A12: R11 | B12: Thiếu GPU: hết quota Kaggle/Colab, máy nhà chỉ có GTX 1660 Ti 6GB | C12: Hạ tầng | D12: 2 | E12: 2 | F12: =IF(OR(D12="",E12=""),"",D12*E12) | G12: Còn <10 giờ quota trong tuần có đợt chạy lớn | H12: Lên lịch các đợt chạy lớn trước, lưu checkpoint, dùng nhiều tài khoản trong nhóm | I12: Giảm số seed/prompt, ghi rõ trong báo cáo | J12: Quân | K12: Mở | L12: 46291
A13: R12 | B13: Demo không chạy trên máy hội đồng | C13: Demo | D13: 1 | E13: 2 | F13: =IF(OR(D13="",E13=""),"",D13*E13) | G13: Chưa chạy thử demo trên máy nào khác máy dev | H13: Chạy thử trên máy của người khác trong nhóm trước 30/11 | I13: Chuẩn bị video quay màn hình dự phòng | J13: Thắng | K13: Mở | L13: 46291
F14: =IF(OR(D14="",E14=""),"",D14*E14)
F15: =IF(OR(D15="",E15=""),"",D15*E15)
F16: =IF(OR(D16="",E16=""),"",D16*E16)
F17: =IF(OR(D17="",E17=""),"",D17*E17)
F18: =IF(OR(D18="",E18=""),"",D18*E18)
F19: =IF(OR(D19="",E19=""),"",D19*E19)
F20: =IF(OR(D20="",E20=""),"",D20*E20)
F21: =IF(OR(D21="",E21=""),"",D21*E21)
F22: =IF(OR(D22="",E22=""),"",D22*E22)
F23: =IF(OR(D23="",E23=""),"",D23*E23)
F24: =IF(OR(D24="",E24=""),"",D24*E24)
F25: =IF(OR(D25="",E25=""),"",D25*E25)

Sheet Quyết định
A1: ID | B1: Ngày | C1: Quyết định | D1: Lý do | E1: Ai quyết | F1: Phương án đã bỏ | G1: Ảnh hưởng tới | H1: Trạng thái | I1: Nguồn
A2: Q01 | B2: ≤ 22/09 | C2: Gộp chốt mô hình + chốt phạm vi vào 1 buổi họp thầy (01/10) | D2: Tiết kiệm thời gian của thầy, chốt sớm để khoá đề cương 03/10 | E2: Nhóm | F2: Họp 2 buổi riêng | G2: P0 | H2: Đã chốt | I2: Timelines.xlsx #4
A3: Q02 | B3: ≤ 22/09 | C3: Benchmark chỉ 3–4 mô hình ứng viên | D3: Tránh dàn trải, kịp hạn P0 | E3: Nhóm | F3: Benchmark 8 mô hình | G3: P0 | H3: Đã chốt | I3: docs/P0_breakdown.md 2.1
A4: Q03 | B4: ≤ 22/09 | C4: Công thức chỉ viết theo DSL, cấm "/", mọi phép chia dùng safe_div | D4: Máy kiểm tra được tự động, không chia cho 0 | E4: Nhóm | F4: Cho AI viết tự do | G4: P0, P4 | H4: Đã chốt | I4: README 4.3
A5: Q04 | B5: 22/09 | C5: Trích biến theo mã số VAS, không dò tên chỉ tiêu | D5: Mã số không bị lỗi chính tả OCR (đã kiểm trên 40 file) | E5: Nhóm | F5: Dò khớp tên tiếng Việt | G5: P1 | H5: Đã chốt | I5: README mục 5
A6: Q05 | B6: ≤ 22/09 | C6: Giữ cả cổ phiếu đã huỷ niêm yết | D6: Tránh survivorship bias | E6: Nhóm | F6: Chỉ lấy mã đang niêm yết | G6: P1 | H6: Đã chốt | I6: README mục 5
A7: Q06 | B7: ≤ 22/09 | C7: Baseline API chỉ chạy trên mẫu con 50 DN × 3 năm | D7: Chi phí API và thời gian | E7: Nhóm | F7: Chạy full | G7: P6 | H7: Đã chốt | I7: Timelines.xlsx #22
A8: Q07 | B8: ≤ 22/09 | C8: Ablation chỉ 2 cấu hình: bỏ RAG, bỏ HITL | D8: Đủ trả lời H2, tiết kiệm thời gian | E8: Nhóm | F8: Thêm cấu hình bỏ validator | G8: P6 | H8: Đã chốt | I8: Timelines.xlsx #23
A9: Q08 | B9: ≤ 22/09 | C9: Giảm số công thức sinh từ 200 xuống ~150 | D9: Vừa sức duyệt tay (HITL) | E9: Nhóm | F9: 200 công thức | G9: P4 | H9: Đã chốt | I9: Timelines.xlsx #16
A10: Q09 | B10: ≤ 22/09 | C10: Trượt CHỐT 2 thì chuyển few-shot + ràng buộc grammar, không đổi mô hình | D10: Đổi mô hình lần nữa sẽ phải chạy lại P0 | E10: Nhóm | F10: Đổi mô hình | G10: P4 | H10: Đã chốt | I10: Timelines.xlsx #18
A11: Q10 | B11: ≤ 22/09 | C11: 3 thứ không được cắt: mô hình chi phí VN, kiểm định thống kê, đóng băng 30/11 | D11: Là đóng góp riêng / điều kiện để bài không bị bắt lỗi | E11: Nhóm | G11: P2, P7 | H11: Đã chốt | I11: README mục 7
A12: Q11 | B12: ≤ 26/09 | C12: Benchmark P0 chạy trên Kaggle T4, lượng tử NF4 4-bit | D12: Máy nhà không đủ; T4 là card phổ thông | E12: Nhóm | F12: Chạy trên GTX 1660 Ti | G12: P0 | H12: Đã chốt | I12: README mục 11
A13: Q12 | B13: 26/09 | C13: Phân vai: Quân = PM + ML, Thắng = Data (+ RAG, demo), Trung = Quant | D13: Cân tải theo pha, mỗi việc 1 người chịu trách nhiệm | E13: Quân | G13: Toàn dự án | H13: Chờ quyết | I13: Chốt ở họp khởi động 27/09
A14: Q13 | B14: 26/09 | C14: Google Sheet là bản cập nhật chính; docs/pm/*.md là bản chụp sau mỗi họp tuần | D14: Ai cũng sửa được Sheet; md giữ lịch sử trong git | E14: Quân | F14: Chỉ dùng md | G14: Quản lý | H14: Đã chốt
A15: Q14 | B15: 26/09 | C15: Kéo pipeline backtest (V19) bắt đầu sớm từ 29/09 thay vì 06/10 | D15: Trung đang ít việc trong P0; backtest dựng được trên dữ liệu giả | E15: Quân | F15: Giữ 06/10 | G15: P2 | H15: Chờ quyết | I15: Chốt ở họp khởi động 27/09
A16: Q21 | B16: 26/09 | C16: C4: Thắng + Trung chấm độc lập cả 80 công thức, Quân làm trọng tài; điểm cuối = trọng tài nếu lệch ≥2, không thì trung bình | D16: Spec yêu cầu 2 người chấm độc lập và báo đồng thuận; Quân dễ đoán ra mô hình | E16: Quân | F16: Chia 3 người mỗi người ~27 mẫu (không đo được đồng thuận) | G16: P0 | H16: Chờ quyết | I16: eval/rubric.md mục 7 — chốt ở họp khởi động 27/09
A17: Q15 | C17: Thuyết minh quý lấy ở đâu? Đề xuất: dùng thuyết minh năm cho 4 quý sau ngày công bố | D17: H2 cần thuyết minh; crawl + OCR quý quá nặng | E17: Thầy | F17: Crawl + OCR PDF quý | G17: P1, P3 | H17: Chờ quyết | I17: README mục 10 #1 — họp 01/10
A18: Q16 | C18: Số liệu quý lấy từ API hay tự OCR? Đề xuất: API | D18: Parser OCR chỉ đọc trung vị 30/65 biến | E18: Thầy | F18: Tự OCR | G18: P1 | H18: Chờ quyết | I18: README mục 10 #2 — họp 01/10
A19: Q17 | C19: Trích con số thật từ thuyết minh thay vì đếm từ khoá? | D19: Để chứng minh thuyết minh đóng góp gì cho H2 | E19: Thầy | F19: Giữ đếm từ khoá | G19: P1, P4 | H19: Chờ quyết | I19: README mục 10 #3 — họp 01/10
A20: Q18 | C20: Loại ngân hàng / chứng khoán khỏi universe? | D20: Mẫu biểu BCTC khác, chỉ 15 biến áp dụng được | E20: Thầy | F20: Giữ và xử lý riêng | G20: P1, P5 | H20: Chờ quyết | I20: README mục 10 #4 — họp 01/10
A21: Q19 | C21: Định vị "giải thích được từ thiết kế" + thêm H5 (tuyến tính làm mốc)? | D21: Ngân hàng, quỹ không chấp nhận hộp đen | E21: Thầy | F21: Không thêm H5 | G21: P5, P8 | H21: Chờ quyết | I21: README mục 10 #5 — họp 01/10
A22: Q20 | C22: Chấp nhận bộ sinh Gemma-4-E2B (5,1B tổng) hay dùng Qwen3.5-2B? | D22: Thầy muốn mô hình "vài trăm triệu" | E22: Thầy | F22: Qwen3.5-2B | G22: P4 | H22: Chờ quyết | I22: README mục 10 #6 — họp 01/10

Sheet Họp
A1: Ngày | B1: Loại | C1: Người dự | D1: Người ghi | E1: Đã xong từ lần trước | F1: Đang kẹt | G1: Quyết định (ID) | H1: Việc mới / đổi (ID) | I1: Ghi chú / link biên bản
A2: 46292 | B2: Khởi động (nhóm) | C2: Quân, Thắng, Trung | D2: Quân | G2: Q12, Q14 | H2: V02 | I2: Nội dung: giới thiệu Sheet, thống nhất phân công, chốt giờ họp tuần, giao V14 cho Thắng và V19 cho Trung
A3: 46296 | B3: Họp thầy | C3: Quân, Thắng, Trung, GVHD | D3: Trung | G3: Q15–Q20 | H3: V11, V12 | I3: Chương trình họp: docs/pm/bien_ban/2026-10-01_hop_thay.md

Sheet Check-in
A1: Ngày | B1: Người | C1: Hôm qua xong gì | D1: Hôm nay làm gì | E1: Đang vướng gì | F1: Cần ai giúp
A2: 46291 | B2: Quân | C2: Chốt kết quả benchmark P0 | D2: Dựng bộ quản lý dự án, chuẩn bị họp khởi động | E2: — | F2: —

Sheet Hướng dẫn
A1: Cách dùng bộ quản lý dự án Nico-tick
A3: CÁC TAB
A4: Tổng quan — mốc sắp tới + số việc mỗi người. Tự tính, không sửa.
A5: Việc — mọi việc của dự án. Người phụ trách tự cập nhật Trạng thái, Hạn mới, Ghi chú.
A6: Phân công, Ma trận — ai làm gì, pha nào ai chịu trách nhiệm.
A7: Rủi ro — thứ có thể hỏng, dấu hiệu sớm, phương án. Xem lại mỗi buổi họp tuần.
A8: Quyết định — đã chốt gì, ai chốt, vì sao. Đổi ý thì đặt dòng cũ "Đã thay đổi" và thêm dòng mới, không xoá.
A9: Họp — nhật ký các buổi họp. Biên bản dài để trong docs/pm/bien_ban/.
A10: Check-in — mỗi người 1 dòng/ngày (hoặc nhắn nhóm chat theo đúng 3 câu này).
A12: CỘT XÁM = TỰ TÍNH, ĐỪNG GÕ ĐÈ
A13: Trễ? (tab Việc), Điểm (tab Rủi ro), toàn bộ tab Tổng quan. Ô vàng = cần điền.
A15: TRẠNG THÁI VIỆC
... A37: File Timelines.xlsx giữ nguyên làm kế hoạch gốc (baseline). Theo dõi hằng ngày dùng Sheet này.
